<?xml version="1.0" encoding="utf-8"?>
<!-- This URDF was automatically created by SolidWorks to URDF Exporter! Originally created by Stephen Brawner (brawner@gmail.com) 
     Commit Version: 1.6.0-1-g15f4949  Build Version: 1.6.7594.29634
     For more information, please see http://wiki.ros.org/sw_urdf_exporter -->
<robot
  name="robotv2_4">
  <link name="world"/>    

  <joint name="world_base_joint" type="fixed">
    <origin xyz="0 0 0" rpy="0 0 0"/>
    <parent link="world"/>
    <child link="base_link"/>
  </joint>
  <link
    name="base_link">
    <inertial>
      <origin
        xyz="-2.8639E-33 -2.7198E-18 0.016957"
        rpy="0 0 0" />
      <mass
        value="0.90321" />
      <inertia
        ixx="0.0046411"
        ixy="1.5739E-34"
        ixz="-6.5052E-36"
        iyy="0.0046411"
        iyz="9.8711E-19"
        izz="0.0080135" />
    </inertial>
    <visual>
      <origin
        xyz="0 0 0"
        rpy="0 0 0" />
      <geometry>
        <mesh
          filename="package://robotv2_4/meshes/base_link.STL" />
      </geometry>
      <material
        name="">
        <color
          rgba="0.79216 0.81961 0.93333 1" />
      </material>
    </visual>
    <collision>
      <origin
        xyz="0 0 0"
        rpy="0 0 0" />
      <geometry>
        <mesh
          filename="package://robotv2_4/meshes/base_link.STL" />
      </geometry>
    </collision>
  </link>
  <link
    name="Link1">
    <inertial>
      <origin
        xyz="4.0534E-18 -0.015806 0.22257"
        rpy="0 0 0" />
      <mass
        value="5.7251" />
      <inertia
        ixx="0.13703"
        ixy="-6.237E-19"
        ixz="-1.251E-18"
        iyy="0.13803"
        iyz="0.0082748"
        izz="0.015162" />
    </inertial>
    <visual>
      <origin
        xyz="0 0 0"
        rpy="0 0 0" />
      <geometry>
        <mesh
          filename="package://robotv2_4/meshes/Link1.STL" />
      </geometry>
      <material
        name="">
        <color
          rgba="0.79216 0.81961 0.93333 1" />
      </material>
    </visual>
    <collision>
      <origin
        xyz="0 0 0"
        rpy="0 0 0" />
      <geometry>
        <mesh
          filename="package://robotv2_4/meshes/Link1.STL" />
      </geometry>
    </collision>
  </link>
  <joint
    name="Joint1"
    type="fixed">
    <origin
      xyz="0 0 0.01"
      rpy="0 0 0" />
    <parent
      link="base_link" />
    <child
      link="Link1" />
    <axis
      xyz="0 0 0" />
  </joint>
  <link
    name="Link2">
    <inertial>
      <origin
        xyz="0.21341 2.2612E-08 0.00062928"
        rpy="0 0 0" />
      <mass
        value="5.1936" />
      <inertia
        ixx="0.01455"
        ixy="-3.9138E-08"
        ixz="0.014192"
        iyy="0.1004"
        iyz="-2.7137E-08"
        izz="0.10014" />
    </inertial>
    <visual>
      <origin
        xyz="0 0 0"
        rpy="0 0 0" />
      <geometry>
        <mesh
          filename="package://robotv2_4/meshes/Link2.STL" />
      </geometry>
      <material
        name="">
        <color
          rgba="0.79216 0.81961 0.93333 1" />
      </material>
    </visual>
    <collision>
      <origin
        xyz="0 0 0"
        rpy="0 0 0" />
      <geometry>
        <mesh
          filename="package://robotv2_4/meshes/Link2.STL" />
      </geometry>
    </collision>
  </link>
  <joint
    name="Joint2"
    type="revolute">
    <origin
      xyz="0 0 0.45"
      rpy="1.5708 -1.5708 3.1416" />
    <parent
      link="Link1" />
    <child
      link="Link2" />
    <axis
      xyz="0 0 1" />
    <limit
      lower="-2.3562"
      upper="2.3562"
      effort="0"
      velocity="0" />
    <joint_properties damping="0.0" friction="0.0"/>
  </joint>
  <link
    name="Link3">
    <inertial>
      <origin
        xyz="0.17596 -0.0068623 0.031985"
        rpy="0 0 0" />
      <mass
        value="3.6966" />
      <inertia
        ixx="0.0066264"
        ixy="-7.3118E-05"
        ixz="-0.00042259"
        iyy="0.058934"
        iyz="1.3616E-06"
        izz="0.062779" />
    </inertial>
    <visual>
      <origin
        xyz="0 0 0"
        rpy="0 0 0" />
      <geometry>
        <mesh
          filename="package://robotv2_4/meshes/Link3.STL" />
      </geometry>
      <material
        name="">
        <color
          rgba="0.79216 0.81961 0.93333 1" />
      </material>
    </visual>
    <collision>
      <origin
        xyz="0 0 0"
        rpy="0 0 0" />
      <geometry>
        <mesh
          filename="package://robotv2_4/meshes/Link3.STL" />
      </geometry>
    </collision>
  </link>
  <joint
    name="joint3"
    type="revolute">
    <origin
      xyz="0.39994 0.0069615 0"
      rpy="0 0 0" />
    <parent
      link="Link2" />
    <child
      link="Link3" />
    <axis
      xyz="0 0 1" />
    <limit
      lower="-2.3562"
      upper="2.3562"
      effort="0"
      velocity="0" />
    <joint_properties damping="0.0" friction="0.0"/>
  </joint>
  <link name="tcp"/>    

  <joint name="tcp_joint" type="fixed">
    <origin xyz="0.450 0 0" rpy="0 0 0"/>
    <parent link="Link3"/>
    <child link="tcp"/>
  </joint>




<transmission name="tran_2">
    <type>transmission_interface/SimpleTransmission</type>
    <joint name="Joint2">
        <hardwareInterface>hardware_interface/PositionJointInterface</hardwareInterface>
    </joint>
    <actuator name="actuator2">
        <hardwareInterface>hardware_interface/PositionJointInterface</hardwareInterface>
        <mechanicalReduction>1</mechanicalReduction>
    </actuator>
</transmission>




<transmission name="tran_3">
    <type>transmission_interface/SimpleTransmission</type>
    <joint name="joint3">
        <hardwareInterface>hardware_interface/PositionJointInterface</hardwareInterface>
    </joint>
    <actuator name="actuator3">
        <hardwareInterface>hardware_interface/PositionJointInterface</hardwareInterface>
        <mechanicalReduction>1</mechanicalReduction>
    </actuator>
</transmission>








  <gazebo>
  <plugin name="gazebo_ros_control" filename="libgazebo_ros_control.so">
    <robotNamespace>/</robotNamespace>
    <robotSimType>gazebo_ros_control/DefaultRobotHWSim</robotSimType>
  </plugin>
  </gazebo>
</robot>
